WARNING: MYSQL_OPT_RECONNECT is deprecated and will be removed in a future version.
........s..........s..........s...EEEEE.EEsEEEE.......s...ssssssssssssssEEEEEEEE.EEEEEEEEsEEEE.......s..........s..........Fs.F..F.......s...EEEEE.EEsEEEEEEEEEE.EEEsEEE.......s...
======================================================================
ERROR: test_created_at (test_models.test_city.test_City)
----------------------------------------------------------------------
Traceback (most recent call last):
  File "/usr/local/lib/python3.8/dist-packages/sqlalchemy/orm/clsregistry.py", line 515, in _resolve_name
    rval = d[token]
  File "/usr/local/lib/python3.8/dist-packages/sqlalchemy/util/_collections.py", line 346, in __missing__
    self[key] = val = self.creator(key)
  File "/usr/local/lib/python3.8/dist-packages/sqlalchemy/orm/clsregistry.py", line 483, in _access_cls
    return self.fallback[key]
KeyError: 'Review'

The above exception was the direct cause of the following exception:

Traceback (most recent call last):
  File "/AirBnB_clone_v2/tests/test_models/test_base_model.py", line 91, in test_created_at
    new = self.value()
  File "<string>", line 4, in __init__
  File "/usr/local/lib/python3.8/dist-packages/sqlalchemy/orm/state.py", line 561, in _initialize_instance
    manager.dispatch.init(self, args, kwargs)
  File "/usr/local/lib/python3.8/dist-packages/sqlalchemy/event/attr.py", line 487, in __call__
    fn(*args, **kw)
  File "/usr/local/lib/python3.8/dist-packages/sqlalchemy/orm/mapper.py", line 4391, in _event_on_init
    instrumenting_mapper._check_configure()
  File "/usr/local/lib/python3.8/dist-packages/sqlalchemy/orm/mapper.py", line 2386, in _check_configure
    _configure_registries({self.registry}, cascade=True)
  File "/usr/local/lib/python3.8/dist-packages/sqlalchemy/orm/mapper.py", line 4199, in _configure_registries
    _do_configure_registries(registries, cascade)
  File "/usr/local/lib/python3.8/dist-packages/sqlalchemy/orm/mapper.py", line 4240, in _do_configure_registries
    mapper._post_configure_properties()
  File "/usr/local/lib/python3.8/dist-packages/sqlalchemy/orm/mapper.py", line 2403, in _post_configure_properties
    prop.init()
  File "/usr/local/lib/python3.8/dist-packages/sqlalchemy/orm/interfaces.py", line 578, in init
    self.do_init()
  File "/usr/local/lib/python3.8/dist-packages/sqlalchemy/orm/relationships.py", line 1634, in do_init
    self._setup_entity()
  File "/usr/local/lib/python3.8/dist-packages/sqlalchemy/orm/relationships.py", line 1851, in _setup_entity
    self._clsregistry_resolve_name(argument)(),
  File "/usr/local/lib/python3.8/dist-packages/sqlalchemy/orm/clsregistry.py", line 519, in _resolve_name
    self._raise_for_name(name, err)
  File "/usr/local/lib/python3.8/dist-packages/sqlalchemy/orm/clsregistry.py", line 500, in _raise_for_name
    raise exc.InvalidRequestError(
sqlalchemy.exc.InvalidRequestError: When initializing mapper Mapper[User(users)], expression 'Review' failed to locate a name ('Review'). If this is a class name, consider adding this relationship() to the <class 'models.user.User'> class after both dependent classes have been defined.

======================================================================
ERROR: test_default (test_models.test_city.test_City)
----------------------------------------------------------------------
Traceback (most recent call last):
  File "/AirBnB_clone_v2/tests/test_models/test_base_model.py", line 32, in test_default
    i = self.value()
  File "<string>", line 4, in __init__
  File "/usr/local/lib/python3.8/dist-packages/sqlalchemy/orm/state.py", line 561, in _initialize_instance
    manager.dispatch.init(self, args, kwargs)
  File "/usr/local/lib/python3.8/dist-packages/sqlalchemy/event/attr.py", line 487, in __call__
    fn(*args, **kw)
  File "/usr/local/lib/python3.8/dist-packages/sqlalchemy/orm/mapper.py", line 4391, in _event_on_init
    instrumenting_mapper._check_configure()
  File "/usr/local/lib/python3.8/dist-packages/sqlalchemy/orm/mapper.py", line 2386, in _check_configure
    _configure_registries({self.registry}, cascade=True)
  File "/usr/local/lib/python3.8/dist-packages/sqlalchemy/orm/mapper.py", line 4199, in _configure_registries
    _do_configure_registries(registries, cascade)
  File "/usr/local/lib/python3.8/dist-packages/sqlalchemy/orm/mapper.py", line 4236, in _do_configure_registries
    raise e
sqlalchemy.exc.InvalidRequestError: One or more mappers failed to initialize - can't proceed with initialization of other mappers. Triggering mapper: 'Mapper[User(users)]'. Original exception was: When initializing mapper Mapper[User(users)], expression 'Review' failed to locate a name ('Review'). If this is a class name, consider adding this relationship() to the <class 'models.user.User'> class after both dependent classes have been defined.

======================================================================
ERROR: test_id (test_models.test_city.test_City)
----------------------------------------------------------------------
Traceback (most recent call last):
  File "/AirBnB_clone_v2/tests/test_models/test_base_model.py", line 86, in test_id
    new = self.value()
  File "<string>", line 4, in __init__
  File "/usr/local/lib/python3.8/dist-packages/sqlalchemy/orm/state.py", line 561, in _initialize_instance
    manager.dispatch.init(self, args, kwargs)
  File "/usr/local/lib/python3.8/dist-packages/sqlalchemy/event/attr.py", line 487, in __call__
    fn(*args, **kw)
  File "/usr/local/lib/python3.8/dist-packages/sqlalchemy/orm/mapper.py", line 4391, in _event_on_init
    instrumenting_mapper._check_configure()
  File "/usr/local/lib/python3.8/dist-packages/sqlalchemy/orm/mapper.py", line 2386, in _check_configure
    _configure_registries({self.registry}, cascade=True)
  File "/usr/local/lib/python3.8/dist-packages/sqlalchemy/orm/mapper.py", line 4199, in _configure_registries
    _do_configure_registries(registries, cascade)
  File "/usr/local/lib/python3.8/dist-packages/sqlalchemy/orm/mapper.py", line 4236, in _do_configure_registries
    raise e
sqlalchemy.exc.InvalidRequestError: One or more mappers failed to initialize - can't proceed with initialization of other mappers. Triggering mapper: 'Mapper[User(users)]'. Original exception was: When initializing mapper Mapper[User(users)], expression 'Review' failed to locate a name ('Review'). If this is a class name, consider adding this relationship() to the <class 'models.user.User'> class after both dependent classes have been defined.

======================================================================
ERROR: test_kwargs (test_models.test_city.test_City)
----------------------------------------------------------------------
Traceback (most recent call last):
  File "/AirBnB_clone_v2/tests/test_models/test_base_model.py", line 37, in test_kwargs
    i = self.value()
  File "<string>", line 4, in __init__
  File "/usr/local/lib/python3.8/dist-packages/sqlalchemy/orm/state.py", line 561, in _initialize_instance
    manager.dispatch.init(self, args, kwargs)
  File "/usr/local/lib/python3.8/dist-packages/sqlalchemy/event/attr.py", line 487, in __call__
    fn(*args, **kw)
  File "/usr/local/lib/python3.8/dist-packages/sqlalchemy/orm/mapper.py", line 4391, in _event_on_init
    instrumenting_mapper._check_configure()
  File "/usr/local/lib/python3.8/dist-packages/sqlalchemy/orm/mapper.py", line 2386, in _check_configure
    _configure_registries({self.registry}, cascade=True)
  File "/usr/local/lib/python3.8/dist-packages/sqlalchemy/orm/mapper.py", line 4199, in _configure_registries
    _do_configure_registries(registries, cascade)
  File "/usr/local/lib/python3.8/dist-packages/sqlalchemy/orm/mapper.py", line 4236, in _do_configure_registries
    raise e
sqlalchemy.exc.InvalidRequestError: One or more mappers failed to initialize - can't proceed with initialization of other mappers. Triggering mapper: 'Mapper[User(users)]'. Original exception was: When initializing mapper Mapper[User(users)], expression 'Review' failed to locate a name ('Review'). If this is a class name, consider adding this relationship() to the <class 'models.user.User'> class after both dependent classes have been defined.

======================================================================
ERROR: test_kwargs_int (test_models.test_city.test_City)
----------------------------------------------------------------------
Traceback (most recent call last):
  File "/AirBnB_clone_v2/tests/test_models/test_base_model.py", line 44, in test_kwargs_int
    i = self.value()
  File "<string>", line 4, in __init__
  File "/usr/local/lib/python3.8/dist-packages/sqlalchemy/orm/state.py", line 561, in _initialize_instance
    manager.dispatch.init(self, args, kwargs)
  File "/usr/local/lib/python3.8/dist-packages/sqlalchemy/event/attr.py", line 487, in __call__
    fn(*args, **kw)
  File "/usr/local/lib/python3.8/dist-packages/sqlalchemy/orm/mapper.py", line 4391, in _event_on_init
    instrumenting_mapper._check_configure()
  File "/usr/local/lib/python3.8/dist-packages/sqlalchemy/orm/mapper.py", line 2386, in _check_configure
    _configure_registries({self.registry}, cascade=True)
  File "/usr/local/lib/python3.8/dist-packages/sqlalchemy/orm/mapper.py", line 4199, in _configure_registries
    _do_configure_registries(registries, cascade)
  File "/usr/local/lib/python3.8/dist-packages/sqlalchemy/orm/mapper.py", line 4236, in _do_configure_registries
    raise e
sqlalchemy.exc.InvalidRequestError: One or more mappers failed to initialize - can't proceed with initialization of other mappers. Triggering mapper: 'Mapper[User(users)]'. Original exception was: When initializing mapper Mapper[User(users)], expression 'Review' failed to locate a name ('Review'). If this is a class name, consider adding this relationship() to the <class 'models.user.User'> class after both dependent classes have been defined.

======================================================================
ERROR: test_kwargs_one (test_models.test_city.test_City)
----------------------------------------------------------------------
Traceback (most recent call last):
  File "/AirBnB_clone_v2/tests/test_models/test_base_model.py", line 82, in test_kwargs_one
    new = self.value(**n)
  File "<string>", line 4, in __init__
  File "/usr/local/lib/python3.8/dist-packages/sqlalchemy/orm/state.py", line 561, in _initialize_instance
    manager.dispatch.init(self, args, kwargs)
  File "/usr/local/lib/python3.8/dist-packages/sqlalchemy/event/attr.py", line 487, in __call__
    fn(*args, **kw)
  File "/usr/local/lib/python3.8/dist-packages/sqlalchemy/orm/mapper.py", line 4391, in _event_on_init
    instrumenting_mapper._check_configure()
  File "/usr/local/lib/python3.8/dist-packages/sqlalchemy/orm/mapper.py", line 2386, in _check_configure
    _configure_registries({self.registry}, cascade=True)
  File "/usr/local/lib/python3.8/dist-packages/sqlalchemy/orm/mapper.py", line 4199, in _configure_registries
    _do_configure_registries(registries, cascade)
  File "/usr/local/lib/python3.8/dist-packages/sqlalchemy/orm/mapper.py", line 4236, in _do_configure_registries
    raise e
sqlalchemy.exc.InvalidRequestError: One or more mappers failed to initialize - can't proceed with initialization of other mappers. Triggering mapper: 'Mapper[User(users)]'. Original exception was: When initializing mapper Mapper[User(users)], expression 'Review' failed to locate a name ('Review'). If this is a class name, consider adding this relationship() to the <class 'models.user.User'> class after both dependent classes have been defined.

======================================================================
ERROR: test_name (test_models.test_city.test_City)
----------------------------------------------------------------------
Traceback (most recent call last):
  File "/AirBnB_clone_v2/tests/test_models/test_city.py", line 23, in test_name
    new = self.value()
  File "<string>", line 4, in __init__
  File "/usr/local/lib/python3.8/dist-packages/sqlalchemy/orm/state.py", line 561, in _initialize_instance
    manager.dispatch.init(self, args, kwargs)
  File "/usr/local/lib/python3.8/dist-packages/sqlalchemy/event/attr.py", line 487, in __call__
    fn(*args, **kw)
  File "/usr/local/lib/python3.8/dist-packages/sqlalchemy/orm/mapper.py", line 4391, in _event_on_init
    instrumenting_mapper._check_configure()
  File "/usr/local/lib/python3.8/dist-packages/sqlalchemy/orm/mapper.py", line 2386, in _check_configure
    _configure_registries({self.registry}, cascade=True)
  File "/usr/local/lib/python3.8/dist-packages/sqlalchemy/orm/mapper.py", line 4199, in _configure_registries
    _do_configure_registries(registries, cascade)
  File "/usr/local/lib/python3.8/dist-packages/sqlalchemy/orm/mapper.py", line 4236, in _do_configure_registries
    raise e
sqlalchemy.exc.InvalidRequestError: One or more mappers failed to initialize - can't proceed with initialization of other mappers. Triggering mapper: 'Mapper[User(users)]'. Original exception was: When initializing mapper Mapper[User(users)], expression 'Review' failed to locate a name ('Review'). If this is a class name, consider adding this relationship() to the <class 'models.user.User'> class after both dependent classes have been defined.

======================================================================
ERROR: test_state_id (test_models.test_city.test_City)
----------------------------------------------------------------------
Traceback (most recent call last):
  File "/AirBnB_clone_v2/tests/test_models/test_city.py", line 18, in test_state_id
    new = self.value()
  File "<string>", line 4, in __init__
  File "/usr/local/lib/python3.8/dist-packages/sqlalchemy/orm/state.py", line 561, in _initialize_instance
    manager.dispatch.init(self, args, kwargs)
  File "/usr/local/lib/python3.8/dist-packages/sqlalchemy/event/attr.py", line 487, in __call__
    fn(*args, **kw)
  File "/usr/local/lib/python3.8/dist-packages/sqlalchemy/orm/mapper.py", line 4391, in _event_on_init
    instrumenting_mapper._check_configure()
  File "/usr/local/lib/python3.8/dist-packages/sqlalchemy/orm/mapper.py", line 2386, in _check_configure
    _configure_registries({self.registry}, cascade=True)
  File "/usr/local/lib/python3.8/dist-packages/sqlalchemy/orm/mapper.py", line 4199, in _configure_registries
    _do_configure_registries(registries, cascade)
  File "/usr/local/lib/python3.8/dist-packages/sqlalchemy/orm/mapper.py", line 4236, in _do_configure_registries
    raise e
sqlalchemy.exc.InvalidRequestError: One or more mappers failed to initialize - can't proceed with initialization of other mappers. Triggering mapper: 'Mapper[User(users)]'. Original exception was: When initializing mapper Mapper[User(users)], expression 'Review' failed to locate a name ('Review'). If this is a class name, consider adding this relationship() to the <class 'models.user.User'> class after both dependent classes have been defined.

======================================================================
ERROR: test_str (test_models.test_city.test_City)
----------------------------------------------------------------------
Traceback (most recent call last):
  File "/AirBnB_clone_v2/tests/test_models/test_base_model.py", line 62, in test_str
    i = self.value()
  File "<string>", line 4, in __init__
  File "/usr/local/lib/python3.8/dist-packages/sqlalchemy/orm/state.py", line 561, in _initialize_instance
    manager.dispatch.init(self, args, kwargs)
  File "/usr/local/lib/python3.8/dist-packages/sqlalchemy/event/attr.py", line 487, in __call__
    fn(*args, **kw)
  File "/usr/local/lib/python3.8/dist-packages/sqlalchemy/orm/mapper.py", line 4391, in _event_on_init
    instrumenting_mapper._check_configure()
  File "/usr/local/lib/python3.8/dist-packages/sqlalchemy/orm/mapper.py", line 2386, in _check_configure
    _configure_registries({self.registry}, cascade=True)
  File "/usr/local/lib/python3.8/dist-packages/sqlalchemy/orm/mapper.py", line 4199, in _configure_registries
    _do_configure_registries(registries, cascade)
  File "/usr/local/lib/python3.8/dist-packages/sqlalchemy/orm/mapper.py", line 4236, in _do_configure_registries
    raise e
sqlalchemy.exc.InvalidRequestError: One or more mappers failed to initialize - can't proceed with initialization of other mappers. Triggering mapper: 'Mapper[User(users)]'. Original exception was: When initializing mapper Mapper[User(users)], expression 'Review' failed to locate a name ('Review'). If this is a class name, consider adding this relationship() to the <class 'models.user.User'> class after both dependent classes have been defined.

======================================================================
ERROR: test_todict (test_models.test_city.test_City)
----------------------------------------------------------------------
Traceback (most recent call last):
  File "/AirBnB_clone_v2/tests/test_models/test_base_model.py", line 68, in test_todict
    i = self.value()
  File "<string>", line 4, in __init__
  File "/usr/local/lib/python3.8/dist-packages/sqlalchemy/orm/state.py", line 561, in _initialize_instance
    manager.dispatch.init(self, args, kwargs)
  File "/usr/local/lib/python3.8/dist-packages/sqlalchemy/event/attr.py", line 487, in __call__
    fn(*args, **kw)
  File "/usr/local/lib/python3.8/dist-packages/sqlalchemy/orm/mapper.py", line 4391, in _event_on_init
    instrumenting_mapper._check_configure()
  File "/usr/local/lib/python3.8/dist-packages/sqlalchemy/orm/mapper.py", line 2386, in _check_configure
    _configure_registries({self.registry}, cascade=True)
  File "/usr/local/lib/python3.8/dist-packages/sqlalchemy/orm/mapper.py", line 4199, in _configure_registries
    _do_configure_registries(registries, cascade)
  File "/usr/local/lib/python3.8/dist-packages/sqlalchemy/orm/mapper.py", line 4236, in _do_configure_registries
    raise e
sqlalchemy.exc.InvalidRequestError: One or more mappers failed to initialize - can't proceed with initialization of other mappers. Triggering mapper: 'Mapper[User(users)]'. Original exception was: When initializing mapper Mapper[User(users)], expression 'Review' failed to locate a name ('Review'). If this is a class name, consider adding this relationship() to the <class 'models.user.User'> class after both dependent classes have been defined.

======================================================================
ERROR: test_updated_at (test_models.test_city.test_City)
----------------------------------------------------------------------
Traceback (most recent call last):
  File "/AirBnB_clone_v2/tests/test_models/test_base_model.py", line 96, in test_updated_at
    new = self.value()
  File "<string>", line 4, in __init__
  File "/usr/local/lib/python3.8/dist-packages/sqlalchemy/orm/state.py", line 561, in _initialize_instance
    manager.dispatch.init(self, args, kwargs)
  File "/usr/local/lib/python3.8/dist-packages/sqlalchemy/event/attr.py", line 487, in __call__
    fn(*args, **kw)
  File "/usr/local/lib/python3.8/dist-packages/sqlalchemy/orm/mapper.py", line 4391, in _event_on_init
    instrumenting_mapper._check_configure()
  File "/usr/local/lib/python3.8/dist-packages/sqlalchemy/orm/mapper.py", line 2386, in _check_configure
    _configure_registries({self.registry}, cascade=True)
  File "/usr/local/lib/python3.8/dist-packages/sqlalchemy/orm/mapper.py", line 4199, in _configure_registries
    _do_configure_registries(registries, cascade)
  File "/usr/local/lib/python3.8/dist-packages/sqlalchemy/orm/mapper.py", line 4236, in _do_configure_registries
    raise e
sqlalchemy.exc.InvalidRequestError: One or more mappers failed to initialize - can't proceed with initialization of other mappers. Triggering mapper: 'Mapper[User(users)]'. Original exception was: When initializing mapper Mapper[User(users)], expression 'Review' failed to locate a name ('Review'). If this is a class name, consider adding this relationship() to the <class 'models.user.User'> class after both dependent classes have been defined.

======================================================================
ERROR: test_amenity_ids (test_models.test_place.test_Place)
----------------------------------------------------------------------
Traceback (most recent call last):
  File "/AirBnB_clone_v2/tests/test_models/test_place.py", line 68, in test_amenity_ids
    new = self.value()
  File "<string>", line 4, in __init__
  File "/usr/local/lib/python3.8/dist-packages/sqlalchemy/orm/state.py", line 561, in _initialize_instance
    manager.dispatch.init(self, args, kwargs)
  File "/usr/local/lib/python3.8/dist-packages/sqlalchemy/event/attr.py", line 487, in __call__
    fn(*args, **kw)
  File "/usr/local/lib/python3.8/dist-packages/sqlalchemy/orm/mapper.py", line 4391, in _event_on_init
    instrumenting_mapper._check_configure()
  File "/usr/local/lib/python3.8/dist-packages/sqlalchemy/orm/mapper.py", line 2386, in _check_configure
    _configure_registries({self.registry}, cascade=True)
  File "/usr/local/lib/python3.8/dist-packages/sqlalchemy/orm/mapper.py", line 4199, in _configure_registries
    _do_configure_registries(registries, cascade)
  File "/usr/local/lib/python3.8/dist-packages/sqlalchemy/orm/mapper.py", line 4236, in _do_configure_registries
    raise e
sqlalchemy.exc.InvalidRequestError: One or more mappers failed to initialize - can't proceed with initialization of other mappers. Triggering mapper: 'Mapper[User(users)]'. Original exception was: When initializing mapper Mapper[User(users)], expression 'Review' failed to locate a name ('Review'). If this is a class name, consider adding this relationship() to the <class 'models.user.User'> class after both dependent classes have been defined.

======================================================================
ERROR: test_city_id (test_models.test_place.test_Place)
----------------------------------------------------------------------
Traceback (most recent call last):
  File "/AirBnB_clone_v2/tests/test_models/test_place.py", line 18, in test_city_id
    new = self.value()
  File "<string>", line 4, in __init__
  File "/usr/local/lib/python3.8/dist-packages/sqlalchemy/orm/state.py", line 561, in _initialize_instance
    manager.dispatch.init(self, args, kwargs)
  File "/usr/local/lib/python3.8/dist-packages/sqlalchemy/event/attr.py", line 487, in __call__
    fn(*args, **kw)
  File "/usr/local/lib/python3.8/dist-packages/sqlalchemy/orm/mapper.py", line 4391, in _event_on_init
    instrumenting_mapper._check_configure()
  File "/usr/local/lib/python3.8/dist-packages/sqlalchemy/orm/mapper.py", line 2386, in _check_configure
    _configure_registries({self.registry}, cascade=True)
  File "/usr/local/lib/python3.8/dist-packages/sqlalchemy/orm/mapper.py", line 4199, in _configure_registries
    _do_configure_registries(registries, cascade)
  File "/usr/local/lib/python3.8/dist-packages/sqlalchemy/orm/mapper.py", line 4236, in _do_configure_registries
    raise e
sqlalchemy.exc.InvalidRequestError: One or more mappers failed to initialize - can't proceed with initialization of other mappers. Triggering mapper: 'Mapper[User(users)]'. Original exception was: When initializing mapper Mapper[User(users)], expression 'Review' failed to locate a name ('Review'). If this is a class name, consider adding this relationship() to the <class 'models.user.User'> class after both dependent classes have been defined.

======================================================================
ERROR: test_created_at (test_models.test_place.test_Place)
----------------------------------------------------------------------
Traceback (most recent call last):
  File "/AirBnB_clone_v2/tests/test_models/test_base_model.py", line 91, in test_created_at
    new = self.value()
  File "<string>", line 4, in __init__
  File "/usr/local/lib/python3.8/dist-packages/sqlalchemy/orm/state.py", line 561, in _initialize_instance
    manager.dispatch.init(self, args, kwargs)
  File "/usr/local/lib/python3.8/dist-packages/sqlalchemy/event/attr.py", line 487, in __call__
    fn(*args, **kw)
  File "/usr/local/lib/python3.8/dist-packages/sqlalchemy/orm/mapper.py", line 4391, in _event_on_init
    instrumenting_mapper._check_configure()
  File "/usr/local/lib/python3.8/dist-packages/sqlalchemy/orm/mapper.py", line 2386, in _check_configure
    _configure_registries({self.registry}, cascade=True)
  File "/usr/local/lib/python3.8/dist-packages/sqlalchemy/orm/mapper.py", line 4199, in _configure_registries
    _do_configure_registries(registries, cascade)
  File "/usr/local/lib/python3.8/dist-packages/sqlalchemy/orm/mapper.py", line 4236, in _do_configure_registries
    raise e
sqlalchemy.exc.InvalidRequestError: One or more mappers failed to initialize - can't proceed with initialization of other mappers. Triggering mapper: 'Mapper[User(users)]'. Original exception was: When initializing mapper Mapper[User(users)], expression 'Review' failed to locate a name ('Review'). If this is a class name, consider adding this relationship() to the <class 'models.user.User'> class after both dependent classes have been defined.

======================================================================
ERROR: test_default (test_models.test_place.test_Place)
----------------------------------------------------------------------
Traceback (most recent call last):
  File "/AirBnB_clone_v2/tests/test_models/test_base_model.py", line 32, in test_default
    i = self.value()
  File "<string>", line 4, in __init__
  File "/usr/local/lib/python3.8/dist-packages/sqlalchemy/orm/state.py", line 561, in _initialize_instance
    manager.dispatch.init(self, args, kwargs)
  File "/usr/local/lib/python3.8/dist-packages/sqlalchemy/event/attr.py", line 487, in __call__
    fn(*args, **kw)
  File "/usr/local/lib/python3.8/dist-packages/sqlalchemy/orm/mapper.py", line 4391, in _event_on_init
    instrumenting_mapper._check_configure()
  File "/usr/local/lib/python3.8/dist-packages/sqlalchemy/orm/mapper.py", line 2386, in _check_configure
    _configure_registries({self.registry}, cascade=True)
  File "/usr/local/lib/python3.8/dist-packages/sqlalchemy/orm/mapper.py", line 4199, in _configure_registries
    _do_configure_registries(registries, cascade)
  File "/usr/local/lib/python3.8/dist-packages/sqlalchemy/orm/mapper.py", line 4236, in _do_configure_registries
    raise e
sqlalchemy.exc.InvalidRequestError: One or more mappers failed to initialize - can't proceed with initialization of other mappers. Triggering mapper: 'Mapper[User(users)]'. Original exception was: When initializing mapper Mapper[User(users)], expression 'Review' failed to locate a name ('Review'). If this is a class name, consider adding this relationship() to the <class 'models.user.User'> class after both dependent classes have been defined.

======================================================================
ERROR: test_description (test_models.test_place.test_Place)
----------------------------------------------------------------------
Traceback (most recent call last):
  File "/AirBnB_clone_v2/tests/test_models/test_place.py", line 33, in test_description
    new = self.value()
  File "<string>", line 4, in __init__
  File "/usr/local/lib/python3.8/dist-packages/sqlalchemy/orm/state.py", line 561, in _initialize_instance
    manager.dispatch.init(self, args, kwargs)
  File "/usr/local/lib/python3.8/dist-packages/sqlalchemy/event/attr.py", line 487, in __call__
    fn(*args, **kw)
  File "/usr/local/lib/python3.8/dist-packages/sqlalchemy/orm/mapper.py", line 4391, in _event_on_init
    instrumenting_mapper._check_configure()
  File "/usr/local/lib/python3.8/dist-packages/sqlalchemy/orm/mapper.py", line 2386, in _check_configure
    _configure_registries({self.registry}, cascade=True)
  File "/usr/local/lib/python3.8/dist-packages/sqlalchemy/orm/mapper.py", line 4199, in _configure_registries
    _do_configure_registries(registries, cascade)
  File "/usr/local/lib/python3.8/dist-packages/sqlalchemy/orm/mapper.py", line 4236, in _do_configure_registries
    raise e
sqlalchemy.exc.InvalidRequestError: One or more mappers failed to initialize - can't proceed with initialization of other mappers. Triggering mapper: 'Mapper[User(users)]'. Original exception was: When initializing mapper Mapper[User(users)], expression 'Review' failed to locate a name ('Review'). If this is a class name, consider adding this relationship() to the <class 'models.user.User'> class after both dependent classes have been defined.

======================================================================
ERROR: test_id (test_models.test_place.test_Place)
----------------------------------------------------------------------
Traceback (most recent call last):
  File "/AirBnB_clone_v2/tests/test_models/test_base_model.py", line 86, in test_id
    new = self.value()
  File "<string>", line 4, in __init__
  File "/usr/local/lib/python3.8/dist-packages/sqlalchemy/orm/state.py", line 561, in _initialize_instance
    manager.dispatch.init(self, args, kwargs)
  File "/usr/local/lib/python3.8/dist-packages/sqlalchemy/event/attr.py", line 487, in __call__
    fn(*args, **kw)
  File "/usr/local/lib/python3.8/dist-packages/sqlalchemy/orm/mapper.py", line 4391, in _event_on_init
    instrumenting_mapper._check_configure()
  File "/usr/local/lib/python3.8/dist-packages/sqlalchemy/orm/mapper.py", line 2386, in _check_configure
    _configure_registries({self.registry}, cascade=True)
  File "/usr/local/lib/python3.8/dist-packages/sqlalchemy/orm/mapper.py", line 4199, in _configure_registries
    _do_configure_registries(registries, cascade)
  File "/usr/local/lib/python3.8/dist-packages/sqlalchemy/orm/mapper.py", line 4236, in _do_configure_registries
    raise e
sqlalchemy.exc.InvalidRequestError: One or more mappers failed to initialize - can't proceed with initialization of other mappers. Triggering mapper: 'Mapper[User(users)]'. Original exception was: When initializing mapper Mapper[User(users)], expression 'Review' failed to locate a name ('Review'). If this is a class name, consider adding this relationship() to the <class 'models.user.User'> class after both dependent classes have been defined.

======================================================================
ERROR: test_kwargs (test_models.test_place.test_Place)
----------------------------------------------------------------------
Traceback (most recent call last):
  File "/AirBnB_clone_v2/tests/test_models/test_base_model.py", line 37, in test_kwargs
    i = self.value()
  File "<string>", line 4, in __init__
  File "/usr/local/lib/python3.8/dist-packages/sqlalchemy/orm/state.py", line 561, in _initialize_instance
    manager.dispatch.init(self, args, kwargs)
  File "/usr/local/lib/python3.8/dist-packages/sqlalchemy/event/attr.py", line 487, in __call__
    fn(*args, **kw)
  File "/usr/local/lib/python3.8/dist-packages/sqlalchemy/orm/mapper.py", line 4391, in _event_on_init
    instrumenting_mapper._check_configure()
  File "/usr/local/lib/python3.8/dist-packages/sqlalchemy/orm/mapper.py", line 2386, in _check_configure
    _configure_registries({self.registry}, cascade=True)
  File "/usr/local/lib/python3.8/dist-packages/sqlalchemy/orm/mapper.py", line 4199, in _configure_registries
    _do_configure_registries(registries, cascade)
  File "/usr/local/lib/python3.8/dist-packages/sqlalchemy/orm/mapper.py", line 4236, in _do_configure_registries
    raise e
sqlalchemy.exc.InvalidRequestError: One or more mappers failed to initialize - can't proceed with initialization of other mappers. Triggering mapper: 'Mapper[User(users)]'. Original exception was: When initializing mapper Mapper[User(users)], expression 'Review' failed to locate a name ('Review'). If this is a class name, consider adding this relationship() to the <class 'models.user.User'> class after both dependent classes have been defined.

======================================================================
ERROR: test_kwargs_int (test_models.test_place.test_Place)
----------------------------------------------------------------------
Traceback (most recent call last):
  File "/AirBnB_clone_v2/tests/test_models/test_base_model.py", line 44, in test_kwargs_int
    i = self.value()
  File "<string>", line 4, in __init__
  File "/usr/local/lib/python3.8/dist-packages/sqlalchemy/orm/state.py", line 561, in _initialize_instance
    manager.dispatch.init(self, args, kwargs)
  File "/usr/local/lib/python3.8/dist-packages/sqlalchemy/event/attr.py", line 487, in __call__
    fn(*args, **kw)
  File "/usr/local/lib/python3.8/dist-packages/sqlalchemy/orm/mapper.py", line 4391, in _event_on_init
    instrumenting_mapper._check_configure()
  File "/usr/local/lib/python3.8/dist-packages/sqlalchemy/orm/mapper.py", line 2386, in _check_configure
    _configure_registries({self.registry}, cascade=True)
  File "/usr/local/lib/python3.8/dist-packages/sqlalchemy/orm/mapper.py", line 4199, in _configure_registries
    _do_configure_registries(registries, cascade)
  File "/usr/local/lib/python3.8/dist-packages/sqlalchemy/orm/mapper.py", line 4236, in _do_configure_registries
    raise e
sqlalchemy.exc.InvalidRequestError: One or more mappers failed to initialize - can't proceed with initialization of other mappers. Triggering mapper: 'Mapper[User(users)]'. Original exception was: When initializing mapper Mapper[User(users)], expression 'Review' failed to locate a name ('Review'). If this is a class name, consider adding this relationship() to the <class 'models.user.User'> class after both dependent classes have been defined.

======================================================================
ERROR: test_kwargs_one (test_models.test_place.test_Place)
----------------------------------------------------------------------
Traceback (most recent call last):
  File "/AirBnB_clone_v2/tests/test_models/test_base_model.py", line 82, in test_kwargs_one
    new = self.value(**n)
  File "<string>", line 4, in __init__
  File "/usr/local/lib/python3.8/dist-packages/sqlalchemy/orm/state.py", line 561, in _initialize_instance
    manager.dispatch.init(self, args, kwargs)
  File "/usr/local/lib/python3.8/dist-packages/sqlalchemy/event/attr.py", line 487, in __call__
    fn(*args, **kw)
  File "/usr/local/lib/python3.8/dist-packages/sqlalchemy/orm/mapper.py", line 4391, in _event_on_init
    instrumenting_mapper._check_configure()
  File "/usr/local/lib/python3.8/dist-packages/sqlalchemy/orm/mapper.py", line 2386, in _check_configure
    _configure_registries({self.registry}, cascade=True)
  File "/usr/local/lib/python3.8/dist-packages/sqlalchemy/orm/mapper.py", line 4199, in _configure_registries
    _do_configure_registries(registries, cascade)
  File "/usr/local/lib/python3.8/dist-packages/sqlalchemy/orm/mapper.py", line 4236, in _do_configure_registries
    raise e
sqlalchemy.exc.InvalidRequestError: One or more mappers failed to initialize - can't proceed with initialization of other mappers. Triggering mapper: 'Mapper[User(users)]'. Original exception was: When initializing mapper Mapper[User(users)], expression 'Review' failed to locate a name ('Review'). If this is a class name, consider adding this relationship() to the <class 'models.user.User'> class after both dependent classes have been defined.

======================================================================
ERROR: test_latitude (test_models.test_place.test_Place)
----------------------------------------------------------------------
Traceback (most recent call last):
  File "/AirBnB_clone_v2/tests/test_models/test_place.py", line 58, in test_latitude
    new = self.value()
  File "<string>", line 4, in __init__
  File "/usr/local/lib/python3.8/dist-packages/sqlalchemy/orm/state.py", line 561, in _initialize_instance
    manager.dispatch.init(self, args, kwargs)
  File "/usr/local/lib/python3.8/dist-packages/sqlalchemy/event/attr.py", line 487, in __call__
    fn(*args, **kw)
  File "/usr/local/lib/python3.8/dist-packages/sqlalchemy/orm/mapper.py", line 4391, in _event_on_init
    instrumenting_mapper._check_configure()
  File "/usr/local/lib/python3.8/dist-packages/sqlalchemy/orm/mapper.py", line 2386, in _check_configure
    _configure_registries({self.registry}, cascade=True)
  File "/usr/local/lib/python3.8/dist-packages/sqlalchemy/orm/mapper.py", line 4199, in _configure_registries
    _do_configure_registries(registries, cascade)
  File "/usr/local/lib/python3.8/dist-packages/sqlalchemy/orm/mapper.py", line 4236, in _do_configure_registries
    raise e
sqlalchemy.exc.InvalidRequestError: One or more mappers failed to initialize - can't proceed with initialization of other mappers. Triggering mapper: 'Mapper[User(users)]'. Original exception was: When initializing mapper Mapper[User(users)], expression 'Review' failed to locate a name ('Review'). If this is a class name, consider adding this relationship() to the <class 'models.user.User'> class after both dependent classes have been defined.

======================================================================
ERROR: test_longitude (test_models.test_place.test_Place)
----------------------------------------------------------------------
Traceback (most recent call last):
  File "/AirBnB_clone_v2/tests/test_models/test_place.py", line 63, in test_longitude
    new = self.value()
  File "<string>", line 4, in __init__
  File "/usr/local/lib/python3.8/dist-packages/sqlalchemy/orm/state.py", line 561, in _initialize_instance
    manager.dispatch.init(self, args, kwargs)
  File "/usr/local/lib/python3.8/dist-packages/sqlalchemy/event/attr.py", line 487, in __call__
    fn(*args, **kw)
  File "/usr/local/lib/python3.8/dist-packages/sqlalchemy/orm/mapper.py", line 4391, in _event_on_init
    instrumenting_mapper._check_configure()
  File "/usr/local/lib/python3.8/dist-packages/sqlalchemy/orm/mapper.py", line 2386, in _check_configure
    _configure_registries({self.registry}, cascade=True)
  File "/usr/local/lib/python3.8/dist-packages/sqlalchemy/orm/mapper.py", line 4199, in _configure_registries
    _do_configure_registries(registries, cascade)
  File "/usr/local/lib/python3.8/dist-packages/sqlalchemy/orm/mapper.py", line 4236, in _do_configure_registries
    raise e
sqlalchemy.exc.InvalidRequestError: One or more mappers failed to initialize - can't proceed with initialization of other mappers. Triggering mapper: 'Mapper[User(users)]'. Original exception was: When initializing mapper Mapper[User(users)], expression 'Review' failed to locate a name ('Review'). If this is a class name, consider adding this relationship() to the <class 'models.user.User'> class after both dependent classes have been defined.

======================================================================
ERROR: test_max_guest (test_models.test_place.test_Place)
----------------------------------------------------------------------
Traceback (most recent call last):
  File "/AirBnB_clone_v2/tests/test_models/test_place.py", line 48, in test_max_guest
    new = self.value()
  File "<string>", line 4, in __init__
  File "/usr/local/lib/python3.8/dist-packages/sqlalchemy/orm/state.py", line 561, in _initialize_instance
    manager.dispatch.init(self, args, kwargs)
  File "/usr/local/lib/python3.8/dist-packages/sqlalchemy/event/attr.py", line 487, in __call__
    fn(*args, **kw)
  File "/usr/local/lib/python3.8/dist-packages/sqlalchemy/orm/mapper.py", line 4391, in _event_on_init
    instrumenting_mapper._check_configure()
  File "/usr/local/lib/python3.8/dist-packages/sqlalchemy/orm/mapper.py", line 2386, in _check_configure
    _configure_registries({self.registry}, cascade=True)
  File "/usr/local/lib/python3.8/dist-packages/sqlalchemy/orm/mapper.py", line 4199, in _configure_registries
    _do_configure_registries(registries, cascade)
  File "/usr/local/lib/python3.8/dist-packages/sqlalchemy/orm/mapper.py", line 4236, in _do_configure_registries
    raise e
sqlalchemy.exc.InvalidRequestError: One or more mappers failed to initialize - can't proceed with initialization of other mappers. Triggering mapper: 'Mapper[User(users)]'. Original exception was: When initializing mapper Mapper[User(users)], expression 'Review' failed to locate a name ('Review'). If this is a class name, consider adding this relationship() to the <class 'models.user.User'> class after both dependent classes have been defined.

======================================================================
ERROR: test_name (test_models.test_place.test_Place)
----------------------------------------------------------------------
Traceback (most recent call last):
  File "/AirBnB_clone_v2/tests/test_models/test_place.py", line 28, in test_name
    new = self.value()
  File "<string>", line 4, in __init__
  File "/usr/local/lib/python3.8/dist-packages/sqlalchemy/orm/state.py", line 561, in _initialize_instance
    manager.dispatch.init(self, args, kwargs)
  File "/usr/local/lib/python3.8/dist-packages/sqlalchemy/event/attr.py", line 487, in __call__
    fn(*args, **kw)
  File "/usr/local/lib/python3.8/dist-packages/sqlalchemy/orm/mapper.py", line 4391, in _event_on_init
    instrumenting_mapper._check_configure()
  File "/usr/local/lib/python3.8/dist-packages/sqlalchemy/orm/mapper.py", line 2386, in _check_configure
    _configure_registries({self.registry}, cascade=True)
  File "/usr/local/lib/python3.8/dist-packages/sqlalchemy/orm/mapper.py", line 4199, in _configure_registries
    _do_configure_registries(registries, cascade)
  File "/usr/local/lib/python3.8/dist-packages/sqlalchemy/orm/mapper.py", line 4236, in _do_configure_registries
    raise e
sqlalchemy.exc.InvalidRequestError: One or more mappers failed to initialize - can't proceed with initialization of other mappers. Triggering mapper: 'Mapper[User(users)]'. Original exception was: When initializing mapper Mapper[User(users)], expression 'Review' failed to locate a name ('Review'). If this is a class name, consider adding this relationship() to the <class 'models.user.User'> class after both dependent classes have been defined.

======================================================================
ERROR: test_number_bathrooms (test_models.test_place.test_Place)
----------------------------------------------------------------------
Traceback (most recent call last):
  File "/AirBnB_clone_v2/tests/test_models/test_place.py", line 43, in test_number_bathrooms
    new = self.value()
  File "<string>", line 4, in __init__
  File "/usr/local/lib/python3.8/dist-packages/sqlalchemy/orm/state.py", line 561, in _initialize_instance
    manager.dispatch.init(self, args, kwargs)
  File "/usr/local/lib/python3.8/dist-packages/sqlalchemy/event/attr.py", line 487, in __call__
    fn(*args, **kw)
  File "/usr/local/lib/python3.8/dist-packages/sqlalchemy/orm/mapper.py", line 4391, in _event_on_init
    instrumenting_mapper._check_configure()
  File "/usr/local/lib/python3.8/dist-packages/sqlalchemy/orm/mapper.py", line 2386, in _check_configure
    _configure_registries({self.registry}, cascade=True)
  File "/usr/local/lib/python3.8/dist-packages/sqlalchemy/orm/mapper.py", line 4199, in _configure_registries
    _do_configure_registries(registries, cascade)
  File "/usr/local/lib/python3.8/dist-packages/sqlalchemy/orm/mapper.py", line 4236, in _do_configure_registries
    raise e
sqlalchemy.exc.InvalidRequestError: One or more mappers failed to initialize - can't proceed with initialization of other mappers. Triggering mapper: 'Mapper[User(users)]'. Original exception was: When initializing mapper Mapper[User(users)], expression 'Review' failed to locate a name ('Review'). If this is a class name, consider adding this relationship() to the <class 'models.user.User'> class after both dependent classes have been defined.

======================================================================
ERROR: test_number_rooms (test_models.test_place.test_Place)
----------------------------------------------------------------------
Traceback (most recent call last):
  File "/AirBnB_clone_v2/tests/test_models/test_place.py", line 38, in test_number_rooms
    new = self.value()
  File "<string>", line 4, in __init__
  File "/usr/local/lib/python3.8/dist-packages/sqlalchemy/orm/state.py", line 561, in _initialize_instance
    manager.dispatch.init(self, args, kwargs)
  File "/usr/local/lib/python3.8/dist-packages/sqlalchemy/event/attr.py", line 487, in __call__
    fn(*args, **kw)
  File "/usr/local/lib/python3.8/dist-packages/sqlalchemy/orm/mapper.py", line 4391, in _event_on_init
    instrumenting_mapper._check_configure()
  File "/usr/local/lib/python3.8/dist-packages/sqlalchemy/orm/mapper.py", line 2386, in _check_configure
    _configure_registries({self.registry}, cascade=True)
  File "/usr/local/lib/python3.8/dist-packages/sqlalchemy/orm/mapper.py", line 4199, in _configure_registries
    _do_configure_registries(registries, cascade)
  File "/usr/local/lib/python3.8/dist-packages/sqlalchemy/orm/mapper.py", line 4236, in _do_configure_registries
    raise e
sqlalchemy.exc.InvalidRequestError: One or more mappers failed to initialize - can't proceed with initialization of other mappers. Triggering mapper: 'Mapper[User(users)]'. Original exception was: When initializing mapper Mapper[User(users)], expression 'Review' failed to locate a name ('Review'). If this is a class name, consider adding this relationship() to the <class 'models.user.User'> class after both dependent classes have been defined.

======================================================================
ERROR: test_price_by_night (test_models.test_place.test_Place)
----------------------------------------------------------------------
Traceback (most recent call last):
  File "/AirBnB_clone_v2/tests/test_models/test_place.py", line 53, in test_price_by_night
    new = self.value()
  File "<string>", line 4, in __init__
  File "/usr/local/lib/python3.8/dist-packages/sqlalchemy/orm/state.py", line 561, in _initialize_instance
    manager.dispatch.init(self, args, kwargs)
  File "/usr/local/lib/python3.8/dist-packages/sqlalchemy/event/attr.py", line 487, in __call__
    fn(*args, **kw)
  File "/usr/local/lib/python3.8/dist-packages/sqlalchemy/orm/mapper.py", line 4391, in _event_on_init
    instrumenting_mapper._check_configure()
  File "/usr/local/lib/python3.8/dist-packages/sqlalchemy/orm/mapper.py", line 2386, in _check_configure
    _configure_registries({self.registry}, cascade=True)
  File "/usr/local/lib/python3.8/dist-packages/sqlalchemy/orm/mapper.py", line 4199, in _configure_registries
    _do_configure_registries(registries, cascade)
  File "/usr/local/lib/python3.8/dist-packages/sqlalchemy/orm/mapper.py", line 4236, in _do_configure_registries
    raise e
sqlalchemy.exc.InvalidRequestError: One or more mappers failed to initialize - can't proceed with initialization of other mappers. Triggering mapper: 'Mapper[User(users)]'. Original exception was: When initializing mapper Mapper[User(users)], expression 'Review' failed to locate a name ('Review'). If this is a class name, consider adding this relationship() to the <class 'models.user.User'> class after both dependent classes have been defined.

======================================================================
ERROR: test_str (test_models.test_place.test_Place)
----------------------------------------------------------------------
Traceback (most recent call last):
  File "/AirBnB_clone_v2/tests/test_models/test_base_model.py", line 62, in test_str
    i = self.value()
  File "<string>", line 4, in __init__
  File "/usr/local/lib/python3.8/dist-packages/sqlalchemy/orm/state.py", line 561, in _initialize_instance
    manager.dispatch.init(self, args, kwargs)
  File "/usr/local/lib/python3.8/dist-packages/sqlalchemy/event/attr.py", line 487, in __call__
    fn(*args, **kw)
  File "/usr/local/lib/python3.8/dist-packages/sqlalchemy/orm/mapper.py", line 4391, in _event_on_init
    instrumenting_mapper._check_configure()
  File "/usr/local/lib/python3.8/dist-packages/sqlalchemy/orm/mapper.py", line 2386, in _check_configure
    _configure_registries({self.registry}, cascade=True)
  File "/usr/local/lib/python3.8/dist-packages/sqlalchemy/orm/mapper.py", line 4199, in _configure_registries
    _do_configure_registries(registries, cascade)
  File "/usr/local/lib/python3.8/dist-packages/sqlalchemy/orm/mapper.py", line 4236, in _do_configure_registries
    raise e
sqlalchemy.exc.InvalidRequestError: One or more mappers failed to initialize - can't proceed with initialization of other mappers. Triggering mapper: 'Mapper[User(users)]'. Original exception was: When initializing mapper Mapper[User(users)], expression 'Review' failed to locate a name ('Review'). If this is a class name, consider adding this relationship() to the <class 'models.user.User'> class after both dependent classes have been defined.

======================================================================
ERROR: test_todict (test_models.test_place.test_Place)
----------------------------------------------------------------------
Traceback (most recent call last):
  File "/AirBnB_clone_v2/tests/test_models/test_base_model.py", line 68, in test_todict
    i = self.value()
  File "<string>", line 4, in __init__
  File "/usr/local/lib/python3.8/dist-packages/sqlalchemy/orm/state.py", line 561, in _initialize_instance
    manager.dispatch.init(self, args, kwargs)
  File "/usr/local/lib/python3.8/dist-packages/sqlalchemy/event/attr.py", line 487, in __call__
    fn(*args, **kw)
  File "/usr/local/lib/python3.8/dist-packages/sqlalchemy/orm/mapper.py", line 4391, in _event_on_init
    instrumenting_mapper._check_configure()
  File "/usr/local/lib/python3.8/dist-packages/sqlalchemy/orm/mapper.py", line 2386, in _check_configure
    _configure_registries({self.registry}, cascade=True)
  File "/usr/local/lib/python3.8/dist-packages/sqlalchemy/orm/mapper.py", line 4199, in _configure_registries
    _do_configure_registries(registries, cascade)
  File "/usr/local/lib/python3.8/dist-packages/sqlalchemy/orm/mapper.py", line 4236, in _do_configure_registries
    raise e
sqlalchemy.exc.InvalidRequestError: One or more mappers failed to initialize - can't proceed with initialization of other mappers. Triggering mapper: 'Mapper[User(users)]'. Original exception was: When initializing mapper Mapper[User(users)], expression 'Review' failed to locate a name ('Review'). If this is a class name, consider adding this relationship() to the <class 'models.user.User'> class after both dependent classes have been defined.

======================================================================
ERROR: test_updated_at (test_models.test_place.test_Place)
----------------------------------------------------------------------
Traceback (most recent call last):
  File "/AirBnB_clone_v2/tests/test_models/test_base_model.py", line 96, in test_updated_at
    new = self.value()
  File "<string>", line 4, in __init__
  File "/usr/local/lib/python3.8/dist-packages/sqlalchemy/orm/state.py", line 561, in _initialize_instance
    manager.dispatch.init(self, args, kwargs)
  File "/usr/local/lib/python3.8/dist-packages/sqlalchemy/event/attr.py", line 487, in __call__
    fn(*args, **kw)
  File "/usr/local/lib/python3.8/dist-packages/sqlalchemy/orm/mapper.py", line 4391, in _event_on_init
    instrumenting_mapper._check_configure()
  File "/usr/local/lib/python3.8/dist-packages/sqlalchemy/orm/mapper.py", line 2386, in _check_configure
    _configure_registries({self.registry}, cascade=True)
  File "/usr/local/lib/python3.8/dist-packages/sqlalchemy/orm/mapper.py", line 4199, in _configure_registries
    _do_configure_registries(registries, cascade)
  File "/usr/local/lib/python3.8/dist-packages/sqlalchemy/orm/mapper.py", line 4236, in _do_configure_registries
    raise e
sqlalchemy.exc.InvalidRequestError: One or more mappers failed to initialize - can't proceed with initialization of other mappers. Triggering mapper: 'Mapper[User(users)]'. Original exception was: When initializing mapper Mapper[User(users)], expression 'Review' failed to locate a name ('Review'). If this is a class name, consider adding this relationship() to the <class 'models.user.User'> class after both dependent classes have been defined.

======================================================================
ERROR: test_user_id (test_models.test_place.test_Place)
----------------------------------------------------------------------
Traceback (most recent call last):
  File "/AirBnB_clone_v2/tests/test_models/test_place.py", line 23, in test_user_id
    new = self.value()
  File "<string>", line 4, in __init__
  File "/usr/local/lib/python3.8/dist-packages/sqlalchemy/orm/state.py", line 561, in _initialize_instance
    manager.dispatch.init(self, args, kwargs)
  File "/usr/local/lib/python3.8/dist-packages/sqlalchemy/event/attr.py", line 487, in __call__
    fn(*args, **kw)
  File "/usr/local/lib/python3.8/dist-packages/sqlalchemy/orm/mapper.py", line 4391, in _event_on_init
    instrumenting_mapper._check_configure()
  File "/usr/local/lib/python3.8/dist-packages/sqlalchemy/orm/mapper.py", line 2386, in _check_configure
    _configure_registries({self.registry}, cascade=True)
  File "/usr/local/lib/python3.8/dist-packages/sqlalchemy/orm/mapper.py", line 4199, in _configure_registries
    _do_configure_registries(registries, cascade)
  File "/usr/local/lib/python3.8/dist-packages/sqlalchemy/orm/mapper.py", line 4236, in _do_configure_registries
    raise e
sqlalchemy.exc.InvalidRequestError: One or more mappers failed to initialize - can't proceed with initialization of other mappers. Triggering mapper: 'Mapper[User(users)]'. Original exception was: When initializing mapper Mapper[User(users)], expression 'Review' failed to locate a name ('Review'). If this is a class name, consider adding this relationship() to the <class 'models.user.User'> class after both dependent classes have been defined.

======================================================================
ERROR: test_created_at (test_models.test_state.test_state)
----------------------------------------------------------------------
Traceback (most recent call last):
  File "/AirBnB_clone_v2/tests/test_models/test_base_model.py", line 91, in test_created_at
    new = self.value()
  File "<string>", line 4, in __init__
  File "/usr/local/lib/python3.8/dist-packages/sqlalchemy/orm/state.py", line 561, in _initialize_instance
    manager.dispatch.init(self, args, kwargs)
  File "/usr/local/lib/python3.8/dist-packages/sqlalchemy/event/attr.py", line 487, in __call__
    fn(*args, **kw)
  File "/usr/local/lib/python3.8/dist-packages/sqlalchemy/orm/mapper.py", line 4391, in _event_on_init
    instrumenting_mapper._check_configure()
  File "/usr/local/lib/python3.8/dist-packages/sqlalchemy/orm/mapper.py", line 2386, in _check_configure
    _configure_registries({self.registry}, cascade=True)
  File "/usr/local/lib/python3.8/dist-packages/sqlalchemy/orm/mapper.py", line 4199, in _configure_registries
    _do_configure_registries(registries, cascade)
  File "/usr/local/lib/python3.8/dist-packages/sqlalchemy/orm/mapper.py", line 4236, in _do_configure_registries
    raise e
sqlalchemy.exc.InvalidRequestError: One or more mappers failed to initialize - can't proceed with initialization of other mappers. Triggering mapper: 'Mapper[User(users)]'. Original exception was: When initializing mapper Mapper[User(users)], expression 'Review' failed to locate a name ('Review'). If this is a class name, consider adding this relationship() to the <class 'models.user.User'> class after both dependent classes have been defined.

======================================================================
ERROR: test_default (test_models.test_state.test_state)
----------------------------------------------------------------------
Traceback (most recent call last):
  File "/AirBnB_clone_v2/tests/test_models/test_base_model.py", line 32, in test_default
    i = self.value()
  File "<string>", line 4, in __init__
  File "/usr/local/lib/python3.8/dist-packages/sqlalchemy/orm/state.py", line 561, in _initialize_instance
    manager.dispatch.init(self, args, kwargs)
  File "/usr/local/lib/python3.8/dist-packages/sqlalchemy/event/attr.py", line 487, in __call__
    fn(*args, **kw)
  File "/usr/local/lib/python3.8/dist-packages/sqlalchemy/orm/mapper.py", line 4391, in _event_on_init
    instrumenting_mapper._check_configure()
  File "/usr/local/lib/python3.8/dist-packages/sqlalchemy/orm/mapper.py", line 2386, in _check_configure
    _configure_registries({self.registry}, cascade=True)
  File "/usr/local/lib/python3.8/dist-packages/sqlalchemy/orm/mapper.py", line 4199, in _configure_registries
    _do_configure_registries(registries, cascade)
  File "/usr/local/lib/python3.8/dist-packages/sqlalchemy/orm/mapper.py", line 4236, in _do_configure_registries
    raise e
sqlalchemy.exc.InvalidRequestError: One or more mappers failed to initialize - can't proceed with initialization of other mappers. Triggering mapper: 'Mapper[User(users)]'. Original exception was: When initializing mapper Mapper[User(users)], expression 'Review' failed to locate a name ('Review'). If this is a class name, consider adding this relationship() to the <class 'models.user.User'> class after both dependent classes have been defined.

======================================================================
ERROR: test_id (test_models.test_state.test_state)
----------------------------------------------------------------------
Traceback (most recent call last):
  File "/AirBnB_clone_v2/tests/test_models/test_base_model.py", line 86, in test_id
    new = self.value()
  File "<string>", line 4, in __init__
  File "/usr/local/lib/python3.8/dist-packages/sqlalchemy/orm/state.py", line 561, in _initialize_instance
    manager.dispatch.init(self, args, kwargs)
  File "/usr/local/lib/python3.8/dist-packages/sqlalchemy/event/attr.py", line 487, in __call__
    fn(*args, **kw)
  File "/usr/local/lib/python3.8/dist-packages/sqlalchemy/orm/mapper.py", line 4391, in _event_on_init
    instrumenting_mapper._check_configure()
  File "/usr/local/lib/python3.8/dist-packages/sqlalchemy/orm/mapper.py", line 2386, in _check_configure
    _configure_registries({self.registry}, cascade=True)
  File "/usr/local/lib/python3.8/dist-packages/sqlalchemy/orm/mapper.py", line 4199, in _configure_registries
    _do_configure_registries(registries, cascade)
  File "/usr/local/lib/python3.8/dist-packages/sqlalchemy/orm/mapper.py", line 4236, in _do_configure_registries
    raise e
sqlalchemy.exc.InvalidRequestError: One or more mappers failed to initialize - can't proceed with initialization of other mappers. Triggering mapper: 'Mapper[User(users)]'. Original exception was: When initializing mapper Mapper[User(users)], expression 'Review' failed to locate a name ('Review'). If this is a class name, consider adding this relationship() to the <class 'models.user.User'> class after both dependent classes have been defined.

======================================================================
ERROR: test_kwargs (test_models.test_state.test_state)
----------------------------------------------------------------------
Traceback (most recent call last):
  File "/AirBnB_clone_v2/tests/test_models/test_base_model.py", line 37, in test_kwargs
    i = self.value()
  File "<string>", line 4, in __init__
  File "/usr/local/lib/python3.8/dist-packages/sqlalchemy/orm/state.py", line 561, in _initialize_instance
    manager.dispatch.init(self, args, kwargs)
  File "/usr/local/lib/python3.8/dist-packages/sqlalchemy/event/attr.py", line 487, in __call__
    fn(*args, **kw)
  File "/usr/local/lib/python3.8/dist-packages/sqlalchemy/orm/mapper.py", line 4391, in _event_on_init
    instrumenting_mapper._check_configure()
  File "/usr/local/lib/python3.8/dist-packages/sqlalchemy/orm/mapper.py", line 2386, in _check_configure
    _configure_registries({self.registry}, cascade=True)
  File "/usr/local/lib/python3.8/dist-packages/sqlalchemy/orm/mapper.py", line 4199, in _configure_registries
    _do_configure_registries(registries, cascade)
  File "/usr/local/lib/python3.8/dist-packages/sqlalchemy/orm/mapper.py", line 4236, in _do_configure_registries
    raise e
sqlalchemy.exc.InvalidRequestError: One or more mappers failed to initialize - can't proceed with initialization of other mappers. Triggering mapper: 'Mapper[User(users)]'. Original exception was: When initializing mapper Mapper[User(users)], expression 'Review' failed to locate a name ('Review'). If this is a class name, consider adding this relationship() to the <class 'models.user.User'> class after both dependent classes have been defined.

======================================================================
ERROR: test_kwargs_int (test_models.test_state.test_state)
----------------------------------------------------------------------
Traceback (most recent call last):
  File "/AirBnB_clone_v2/tests/test_models/test_base_model.py", line 44, in test_kwargs_int
    i = self.value()
  File "<string>", line 4, in __init__
  File "/usr/local/lib/python3.8/dist-packages/sqlalchemy/orm/state.py", line 561, in _initialize_instance
    manager.dispatch.init(self, args, kwargs)
  File "/usr/local/lib/python3.8/dist-packages/sqlalchemy/event/attr.py", line 487, in __call__
    fn(*args, **kw)
  File "/usr/local/lib/python3.8/dist-packages/sqlalchemy/orm/mapper.py", line 4391, in _event_on_init
    instrumenting_mapper._check_configure()
  File "/usr/local/lib/python3.8/dist-packages/sqlalchemy/orm/mapper.py", line 2386, in _check_configure
    _configure_registries({self.registry}, cascade=True)
  File "/usr/local/lib/python3.8/dist-packages/sqlalchemy/orm/mapper.py", line 4199, in _configure_registries
    _do_configure_registries(registries, cascade)
  File "/usr/local/lib/python3.8/dist-packages/sqlalchemy/orm/mapper.py", line 4236, in _do_configure_registries
    raise e
sqlalchemy.exc.InvalidRequestError: One or more mappers failed to initialize - can't proceed with initialization of other mappers. Triggering mapper: 'Mapper[User(users)]'. Original exception was: When initializing mapper Mapper[User(users)], expression 'Review' failed to locate a name ('Review'). If this is a class name, consider adding this relationship() to the <class 'models.user.User'> class after both dependent classes have been defined.

======================================================================
ERROR: test_kwargs_one (test_models.test_state.test_state)
----------------------------------------------------------------------
Traceback (most recent call last):
  File "/AirBnB_clone_v2/tests/test_models/test_base_model.py", line 82, in test_kwargs_one
    new = self.value(**n)
  File "<string>", line 4, in __init__
  File "/usr/local/lib/python3.8/dist-packages/sqlalchemy/orm/state.py", line 561, in _initialize_instance
    manager.dispatch.init(self, args, kwargs)
  File "/usr/local/lib/python3.8/dist-packages/sqlalchemy/event/attr.py", line 487, in __call__
    fn(*args, **kw)
  File "/usr/local/lib/python3.8/dist-packages/sqlalchemy/orm/mapper.py", line 4391, in _event_on_init
    instrumenting_mapper._check_configure()
  File "/usr/local/lib/python3.8/dist-packages/sqlalchemy/orm/mapper.py", line 2386, in _check_configure
    _configure_registries({self.registry}, cascade=True)
  File "/usr/local/lib/python3.8/dist-packages/sqlalchemy/orm/mapper.py", line 4199, in _configure_registries
    _do_configure_registries(registries, cascade)
  File "/usr/local/lib/python3.8/dist-packages/sqlalchemy/orm/mapper.py", line 4236, in _do_configure_registries
    raise e
sqlalchemy.exc.InvalidRequestError: One or more mappers failed to initialize - can't proceed with initialization of other mappers. Triggering mapper: 'Mapper[User(users)]'. Original exception was: When initializing mapper Mapper[User(users)], expression 'Review' failed to locate a name ('Review'). If this is a class name, consider adding this relationship() to the <class 'models.user.User'> class after both dependent classes have been defined.

======================================================================
ERROR: test_name3 (test_models.test_state.test_state)
----------------------------------------------------------------------
Traceback (most recent call last):
  File "/AirBnB_clone_v2/tests/test_models/test_state.py", line 18, in test_name3
    new = self.value()
  File "<string>", line 4, in __init__
  File "/usr/local/lib/python3.8/dist-packages/sqlalchemy/orm/state.py", line 561, in _initialize_instance
    manager.dispatch.init(self, args, kwargs)
  File "/usr/local/lib/python3.8/dist-packages/sqlalchemy/event/attr.py", line 487, in __call__
    fn(*args, **kw)
  File "/usr/local/lib/python3.8/dist-packages/sqlalchemy/orm/mapper.py", line 4391, in _event_on_init
    instrumenting_mapper._check_configure()
  File "/usr/local/lib/python3.8/dist-packages/sqlalchemy/orm/mapper.py", line 2386, in _check_configure
    _configure_registries({self.registry}, cascade=True)
  File "/usr/local/lib/python3.8/dist-packages/sqlalchemy/orm/mapper.py", line 4199, in _configure_registries
    _do_configure_registries(registries, cascade)
  File "/usr/local/lib/python3.8/dist-packages/sqlalchemy/orm/mapper.py", line 4236, in _do_configure_registries
    raise e
sqlalchemy.exc.InvalidRequestError: One or more mappers failed to initialize - can't proceed with initialization of other mappers. Triggering mapper: 'Mapper[User(users)]'. Original exception was: When initializing mapper Mapper[User(users)], expression 'Review' failed to locate a name ('Review'). If this is a class name, consider adding this relationship() to the <class 'models.user.User'> class after both dependent classes have been defined.

======================================================================
ERROR: test_str (test_models.test_state.test_state)
----------------------------------------------------------------------
Traceback (most recent call last):
  File "/AirBnB_clone_v2/tests/test_models/test_base_model.py", line 62, in test_str
    i = self.value()
  File "<string>", line 4, in __init__
  File "/usr/local/lib/python3.8/dist-packages/sqlalchemy/orm/state.py", line 561, in _initialize_instance
    manager.dispatch.init(self, args, kwargs)
  File "/usr/local/lib/python3.8/dist-packages/sqlalchemy/event/attr.py", line 487, in __call__
    fn(*args, **kw)
  File "/usr/local/lib/python3.8/dist-packages/sqlalchemy/orm/mapper.py", line 4391, in _event_on_init
    instrumenting_mapper._check_configure()
  File "/usr/local/lib/python3.8/dist-packages/sqlalchemy/orm/mapper.py", line 2386, in _check_configure
    _configure_registries({self.registry}, cascade=True)
  File "/usr/local/lib/python3.8/dist-packages/sqlalchemy/orm/mapper.py", line 4199, in _configure_registries
    _do_configure_registries(registries, cascade)
  File "/usr/local/lib/python3.8/dist-packages/sqlalchemy/orm/mapper.py", line 4236, in _do_configure_registries
    raise e
sqlalchemy.exc.InvalidRequestError: One or more mappers failed to initialize - can't proceed with initialization of other mappers. Triggering mapper: 'Mapper[User(users)]'. Original exception was: When initializing mapper Mapper[User(users)], expression 'Review' failed to locate a name ('Review'). If this is a class name, consider adding this relationship() to the <class 'models.user.User'> class after both dependent classes have been defined.

======================================================================
ERROR: test_todict (test_models.test_state.test_state)
----------------------------------------------------------------------
Traceback (most recent call last):
  File "/AirBnB_clone_v2/tests/test_models/test_base_model.py", line 68, in test_todict
    i = self.value()
  File "<string>", line 4, in __init__
  File "/usr/local/lib/python3.8/dist-packages/sqlalchemy/orm/state.py", line 561, in _initialize_instance
    manager.dispatch.init(self, args, kwargs)
  File "/usr/local/lib/python3.8/dist-packages/sqlalchemy/event/attr.py", line 487, in __call__
    fn(*args, **kw)
  File "/usr/local/lib/python3.8/dist-packages/sqlalchemy/orm/mapper.py", line 4391, in _event_on_init
    instrumenting_mapper._check_configure()
  File "/usr/local/lib/python3.8/dist-packages/sqlalchemy/orm/mapper.py", line 2386, in _check_configure
    _configure_registries({self.registry}, cascade=True)
  File "/usr/local/lib/python3.8/dist-packages/sqlalchemy/orm/mapper.py", line 4199, in _configure_registries
    _do_configure_registries(registries, cascade)
  File "/usr/local/lib/python3.8/dist-packages/sqlalchemy/orm/mapper.py", line 4236, in _do_configure_registries
    raise e
sqlalchemy.exc.InvalidRequestError: One or more mappers failed to initialize - can't proceed with initialization of other mappers. Triggering mapper: 'Mapper[User(users)]'. Original exception was: When initializing mapper Mapper[User(users)], expression 'Review' failed to locate a name ('Review'). If this is a class name, consider adding this relationship() to the <class 'models.user.User'> class after both dependent classes have been defined.

======================================================================
ERROR: test_updated_at (test_models.test_state.test_state)
----------------------------------------------------------------------
Traceback (most recent call last):
  File "/AirBnB_clone_v2/tests/test_models/test_base_model.py", line 96, in test_updated_at
    new = self.value()
  File "<string>", line 4, in __init__
  File "/usr/local/lib/python3.8/dist-packages/sqlalchemy/orm/state.py", line 561, in _initialize_instance
    manager.dispatch.init(self, args, kwargs)
  File "/usr/local/lib/python3.8/dist-packages/sqlalchemy/event/attr.py", line 487, in __call__
    fn(*args, **kw)
  File "/usr/local/lib/python3.8/dist-packages/sqlalchemy/orm/mapper.py", line 4391, in _event_on_init
    instrumenting_mapper._check_configure()
  File "/usr/local/lib/python3.8/dist-packages/sqlalchemy/orm/mapper.py", line 2386, in _check_configure
    _configure_registries({self.registry}, cascade=True)
  File "/usr/local/lib/python3.8/dist-packages/sqlalchemy/orm/mapper.py", line 4199, in _configure_registries
    _do_configure_registries(registries, cascade)
  File "/usr/local/lib/python3.8/dist-packages/sqlalchemy/orm/mapper.py", line 4236, in _do_configure_registries
    raise e
sqlalchemy.exc.InvalidRequestError: One or more mappers failed to initialize - can't proceed with initialization of other mappers. Triggering mapper: 'Mapper[User(users)]'. Original exception was: When initializing mapper Mapper[User(users)], expression 'Review' failed to locate a name ('Review'). If this is a class name, consider adding this relationship() to the <class 'models.user.User'> class after both dependent classes have been defined.

======================================================================
ERROR: test_created_at (test_models.test_user.test_User)
----------------------------------------------------------------------
Traceback (most recent call last):
  File "/AirBnB_clone_v2/tests/test_models/test_base_model.py", line 91, in test_created_at
    new = self.value()
  File "<string>", line 4, in __init__
  File "/usr/local/lib/python3.8/dist-packages/sqlalchemy/orm/state.py", line 561, in _initialize_instance
    manager.dispatch.init(self, args, kwargs)
  File "/usr/local/lib/python3.8/dist-packages/sqlalchemy/event/attr.py", line 487, in __call__
    fn(*args, **kw)
  File "/usr/local/lib/python3.8/dist-packages/sqlalchemy/orm/mapper.py", line 4391, in _event_on_init
    instrumenting_mapper._check_configure()
  File "/usr/local/lib/python3.8/dist-packages/sqlalchemy/orm/mapper.py", line 2386, in _check_configure
    _configure_registries({self.registry}, cascade=True)
  File "/usr/local/lib/python3.8/dist-packages/sqlalchemy/orm/mapper.py", line 4199, in _configure_registries
    _do_configure_registries(registries, cascade)
  File "/usr/local/lib/python3.8/dist-packages/sqlalchemy/orm/mapper.py", line 4236, in _do_configure_registries
    raise e
sqlalchemy.exc.InvalidRequestError: One or more mappers failed to initialize - can't proceed with initialization of other mappers. Triggering mapper: 'Mapper[User(users)]'. Original exception was: When initializing mapper Mapper[User(users)], expression 'Review' failed to locate a name ('Review'). If this is a class name, consider adding this relationship() to the <class 'models.user.User'> class after both dependent classes have been defined.

======================================================================
ERROR: test_default (test_models.test_user.test_User)
----------------------------------------------------------------------
Traceback (most recent call last):
  File "/AirBnB_clone_v2/tests/test_models/test_base_model.py", line 32, in test_default
    i = self.value()
  File "<string>", line 4, in __init__
  File "/usr/local/lib/python3.8/dist-packages/sqlalchemy/orm/state.py", line 561, in _initialize_instance
    manager.dispatch.init(self, args, kwargs)
  File "/usr/local/lib/python3.8/dist-packages/sqlalchemy/event/attr.py", line 487, in __call__
    fn(*args, **kw)
  File "/usr/local/lib/python3.8/dist-packages/sqlalchemy/orm/mapper.py", line 4391, in _event_on_init
    instrumenting_mapper._check_configure()
  File "/usr/local/lib/python3.8/dist-packages/sqlalchemy/orm/mapper.py", line 2386, in _check_configure
    _configure_registries({self.registry}, cascade=True)
  File "/usr/local/lib/python3.8/dist-packages/sqlalchemy/orm/mapper.py", line 4199, in _configure_registries
    _do_configure_registries(registries, cascade)
  File "/usr/local/lib/python3.8/dist-packages/sqlalchemy/orm/mapper.py", line 4236, in _do_configure_registries
    raise e
sqlalchemy.exc.InvalidRequestError: One or more mappers failed to initialize - can't proceed with initialization of other mappers. Triggering mapper: 'Mapper[User(users)]'. Original exception was: When initializing mapper Mapper[User(users)], expression 'Review' failed to locate a name ('Review'). If this is a class name, consider adding this relationship() to the <class 'models.user.User'> class after both dependent classes have been defined.

======================================================================
ERROR: test_email (test_models.test_user.test_User)
----------------------------------------------------------------------
Traceback (most recent call last):
  File "/AirBnB_clone_v2/tests/test_models/test_user.py", line 28, in test_email
    new = self.value()
  File "<string>", line 4, in __init__
  File "/usr/local/lib/python3.8/dist-packages/sqlalchemy/orm/state.py", line 561, in _initialize_instance
    manager.dispatch.init(self, args, kwargs)
  File "/usr/local/lib/python3.8/dist-packages/sqlalchemy/event/attr.py", line 487, in __call__
    fn(*args, **kw)
  File "/usr/local/lib/python3.8/dist-packages/sqlalchemy/orm/mapper.py", line 4391, in _event_on_init
    instrumenting_mapper._check_configure()
  File "/usr/local/lib/python3.8/dist-packages/sqlalchemy/orm/mapper.py", line 2386, in _check_configure
    _configure_registries({self.registry}, cascade=True)
  File "/usr/local/lib/python3.8/dist-packages/sqlalchemy/orm/mapper.py", line 4199, in _configure_registries
    _do_configure_registries(registries, cascade)
  File "/usr/local/lib/python3.8/dist-packages/sqlalchemy/orm/mapper.py", line 4236, in _do_configure_registries
    raise e
sqlalchemy.exc.InvalidRequestError: One or more mappers failed to initialize - can't proceed with initialization of other mappers. Triggering mapper: 'Mapper[User(users)]'. Original exception was: When initializing mapper Mapper[User(users)], expression 'Review' failed to locate a name ('Review'). If this is a class name, consider adding this relationship() to the <class 'models.user.User'> class after both dependent classes have been defined.

======================================================================
ERROR: test_first_name (test_models.test_user.test_User)
----------------------------------------------------------------------
Traceback (most recent call last):
  File "/AirBnB_clone_v2/tests/test_models/test_user.py", line 18, in test_first_name
    new = self.value()
  File "<string>", line 4, in __init__
  File "/usr/local/lib/python3.8/dist-packages/sqlalchemy/orm/state.py", line 561, in _initialize_instance
    manager.dispatch.init(self, args, kwargs)
  File "/usr/local/lib/python3.8/dist-packages/sqlalchemy/event/attr.py", line 487, in __call__
    fn(*args, **kw)
  File "/usr/local/lib/python3.8/dist-packages/sqlalchemy/orm/mapper.py", line 4391, in _event_on_init
    instrumenting_mapper._check_configure()
  File "/usr/local/lib/python3.8/dist-packages/sqlalchemy/orm/mapper.py", line 2386, in _check_configure
    _configure_registries({self.registry}, cascade=True)
  File "/usr/local/lib/python3.8/dist-packages/sqlalchemy/orm/mapper.py", line 4199, in _configure_registries
    _do_configure_registries(registries, cascade)
  File "/usr/local/lib/python3.8/dist-packages/sqlalchemy/orm/mapper.py", line 4236, in _do_configure_registries
    raise e
sqlalchemy.exc.InvalidRequestError: One or more mappers failed to initialize - can't proceed with initialization of other mappers. Triggering mapper: 'Mapper[User(users)]'. Original exception was: When initializing mapper Mapper[User(users)], expression 'Review' failed to locate a name ('Review'). If this is a class name, consider adding this relationship() to the <class 'models.user.User'> class after both dependent classes have been defined.

======================================================================
ERROR: test_id (test_models.test_user.test_User)
----------------------------------------------------------------------
Traceback (most recent call last):
  File "/AirBnB_clone_v2/tests/test_models/test_base_model.py", line 86, in test_id
    new = self.value()
  File "<string>", line 4, in __init__
  File "/usr/local/lib/python3.8/dist-packages/sqlalchemy/orm/state.py", line 561, in _initialize_instance
    manager.dispatch.init(self, args, kwargs)
  File "/usr/local/lib/python3.8/dist-packages/sqlalchemy/event/attr.py", line 487, in __call__
    fn(*args, **kw)
  File "/usr/local/lib/python3.8/dist-packages/sqlalchemy/orm/mapper.py", line 4391, in _event_on_init
    instrumenting_mapper._check_configure()
  File "/usr/local/lib/python3.8/dist-packages/sqlalchemy/orm/mapper.py", line 2386, in _check_configure
    _configure_registries({self.registry}, cascade=True)
  File "/usr/local/lib/python3.8/dist-packages/sqlalchemy/orm/mapper.py", line 4199, in _configure_registries
    _do_configure_registries(registries, cascade)
  File "/usr/local/lib/python3.8/dist-packages/sqlalchemy/orm/mapper.py", line 4236, in _do_configure_registries
    raise e
sqlalchemy.exc.InvalidRequestError: One or more mappers failed to initialize - can't proceed with initialization of other mappers. Triggering mapper: 'Mapper[User(users)]'. Original exception was: When initializing mapper Mapper[User(users)], expression 'Review' failed to locate a name ('Review'). If this is a class name, consider adding this relationship() to the <class 'models.user.User'> class after both dependent classes have been defined.

======================================================================
ERROR: test_kwargs (test_models.test_user.test_User)
----------------------------------------------------------------------
Traceback (most recent call last):
  File "/AirBnB_clone_v2/tests/test_models/test_base_model.py", line 37, in test_kwargs
    i = self.value()
  File "<string>", line 4, in __init__
  File "/usr/local/lib/python3.8/dist-packages/sqlalchemy/orm/state.py", line 561, in _initialize_instance
    manager.dispatch.init(self, args, kwargs)
  File "/usr/local/lib/python3.8/dist-packages/sqlalchemy/event/attr.py", line 487, in __call__
    fn(*args, **kw)
  File "/usr/local/lib/python3.8/dist-packages/sqlalchemy/orm/mapper.py", line 4391, in _event_on_init
    instrumenting_mapper._check_configure()
  File "/usr/local/lib/python3.8/dist-packages/sqlalchemy/orm/mapper.py", line 2386, in _check_configure
    _configure_registries({self.registry}, cascade=True)
  File "/usr/local/lib/python3.8/dist-packages/sqlalchemy/orm/mapper.py", line 4199, in _configure_registries
    _do_configure_registries(registries, cascade)
  File "/usr/local/lib/python3.8/dist-packages/sqlalchemy/orm/mapper.py", line 4236, in _do_configure_registries
    raise e
sqlalchemy.exc.InvalidRequestError: One or more mappers failed to initialize - can't proceed with initialization of other mappers. Triggering mapper: 'Mapper[User(users)]'. Original exception was: When initializing mapper Mapper[User(users)], expression 'Review' failed to locate a name ('Review'). If this is a class name, consider adding this relationship() to the <class 'models.user.User'> class after both dependent classes have been defined.

======================================================================
ERROR: test_kwargs_int (test_models.test_user.test_User)
----------------------------------------------------------------------
Traceback (most recent call last):
  File "/AirBnB_clone_v2/tests/test_models/test_base_model.py", line 44, in test_kwargs_int
    i = self.value()
  File "<string>", line 4, in __init__
  File "/usr/local/lib/python3.8/dist-packages/sqlalchemy/orm/state.py", line 561, in _initialize_instance
    manager.dispatch.init(self, args, kwargs)
  File "/usr/local/lib/python3.8/dist-packages/sqlalchemy/event/attr.py", line 487, in __call__
    fn(*args, **kw)
  File "/usr/local/lib/python3.8/dist-packages/sqlalchemy/orm/mapper.py", line 4391, in _event_on_init
    instrumenting_mapper._check_configure()
  File "/usr/local/lib/python3.8/dist-packages/sqlalchemy/orm/mapper.py", line 2386, in _check_configure
    _configure_registries({self.registry}, cascade=True)
  File "/usr/local/lib/python3.8/dist-packages/sqlalchemy/orm/mapper.py", line 4199, in _configure_registries
    _do_configure_registries(registries, cascade)
  File "/usr/local/lib/python3.8/dist-packages/sqlalchemy/orm/mapper.py", line 4236, in _do_configure_registries
    raise e
sqlalchemy.exc.InvalidRequestError: One or more mappers failed to initialize - can't proceed with initialization of other mappers. Triggering mapper: 'Mapper[User(users)]'. Original exception was: When initializing mapper Mapper[User(users)], expression 'Review' failed to locate a name ('Review'). If this is a class name, consider adding this relationship() to the <class 'models.user.User'> class after both dependent classes have been defined.

======================================================================
ERROR: test_kwargs_one (test_models.test_user.test_User)
----------------------------------------------------------------------
Traceback (most recent call last):
  File "/AirBnB_clone_v2/tests/test_models/test_base_model.py", line 82, in test_kwargs_one
    new = self.value(**n)
  File "<string>", line 4, in __init__
  File "/usr/local/lib/python3.8/dist-packages/sqlalchemy/orm/state.py", line 561, in _initialize_instance
    manager.dispatch.init(self, args, kwargs)
  File "/usr/local/lib/python3.8/dist-packages/sqlalchemy/event/attr.py", line 487, in __call__
    fn(*args, **kw)
  File "/usr/local/lib/python3.8/dist-packages/sqlalchemy/orm/mapper.py", line 4391, in _event_on_init
    instrumenting_mapper._check_configure()
  File "/usr/local/lib/python3.8/dist-packages/sqlalchemy/orm/mapper.py", line 2386, in _check_configure
    _configure_registries({self.registry}, cascade=True)
  File "/usr/local/lib/python3.8/dist-packages/sqlalchemy/orm/mapper.py", line 4199, in _configure_registries
    _do_configure_registries(registries, cascade)
  File "/usr/local/lib/python3.8/dist-packages/sqlalchemy/orm/mapper.py", line 4236, in _do_configure_registries
    raise e
sqlalchemy.exc.InvalidRequestError: One or more mappers failed to initialize - can't proceed with initialization of other mappers. Triggering mapper: 'Mapper[User(users)]'. Original exception was: When initializing mapper Mapper[User(users)], expression 'Review' failed to locate a name ('Review'). If this is a class name, consider adding this relationship() to the <class 'models.user.User'> class after both dependent classes have been defined.

======================================================================
ERROR: test_last_name (test_models.test_user.test_User)
----------------------------------------------------------------------
Traceback (most recent call last):
  File "/AirBnB_clone_v2/tests/test_models/test_user.py", line 23, in test_last_name
    new = self.value()
  File "<string>", line 4, in __init__
  File "/usr/local/lib/python3.8/dist-packages/sqlalchemy/orm/state.py", line 561, in _initialize_instance
    manager.dispatch.init(self, args, kwargs)
  File "/usr/local/lib/python3.8/dist-packages/sqlalchemy/event/attr.py", line 487, in __call__
    fn(*args, **kw)
  File "/usr/local/lib/python3.8/dist-packages/sqlalchemy/orm/mapper.py", line 4391, in _event_on_init
    instrumenting_mapper._check_configure()
  File "/usr/local/lib/python3.8/dist-packages/sqlalchemy/orm/mapper.py", line 2386, in _check_configure
    _configure_registries({self.registry}, cascade=True)
  File "/usr/local/lib/python3.8/dist-packages/sqlalchemy/orm/mapper.py", line 4199, in _configure_registries
    _do_configure_registries(registries, cascade)
  File "/usr/local/lib/python3.8/dist-packages/sqlalchemy/orm/mapper.py", line 4236, in _do_configure_registries
    raise e
sqlalchemy.exc.InvalidRequestError: One or more mappers failed to initialize - can't proceed with initialization of other mappers. Triggering mapper: 'Mapper[User(users)]'. Original exception was: When initializing mapper Mapper[User(users)], expression 'Review' failed to locate a name ('Review'). If this is a class name, consider adding this relationship() to the <class 'models.user.User'> class after both dependent classes have been defined.

======================================================================
ERROR: test_password (test_models.test_user.test_User)
----------------------------------------------------------------------
Traceback (most recent call last):
  File "/AirBnB_clone_v2/tests/test_models/test_user.py", line 33, in test_password
    new = self.value()
  File "<string>", line 4, in __init__
  File "/usr/local/lib/python3.8/dist-packages/sqlalchemy/orm/state.py", line 561, in _initialize_instance
    manager.dispatch.init(self, args, kwargs)
  File "/usr/local/lib/python3.8/dist-packages/sqlalchemy/event/attr.py", line 487, in __call__
    fn(*args, **kw)
  File "/usr/local/lib/python3.8/dist-packages/sqlalchemy/orm/mapper.py", line 4391, in _event_on_init
    instrumenting_mapper._check_configure()
  File "/usr/local/lib/python3.8/dist-packages/sqlalchemy/orm/mapper.py", line 2386, in _check_configure
    _configure_registries({self.registry}, cascade=True)
  File "/usr/local/lib/python3.8/dist-packages/sqlalchemy/orm/mapper.py", line 4199, in _configure_registries
    _do_configure_registries(registries, cascade)
  File "/usr/local/lib/python3.8/dist-packages/sqlalchemy/orm/mapper.py", line 4236, in _do_configure_registries
    raise e
sqlalchemy.exc.InvalidRequestError: One or more mappers failed to initialize - can't proceed with initialization of other mappers. Triggering mapper: 'Mapper[User(users)]'. Original exception was: When initializing mapper Mapper[User(users)], expression 'Review' failed to locate a name ('Review'). If this is a class name, consider adding this relationship() to the <class 'models.user.User'> class after both dependent classes have been defined.

======================================================================
ERROR: test_str (test_models.test_user.test_User)
----------------------------------------------------------------------
Traceback (most recent call last):
  File "/AirBnB_clone_v2/tests/test_models/test_base_model.py", line 62, in test_str
    i = self.value()
  File "<string>", line 4, in __init__
  File "/usr/local/lib/python3.8/dist-packages/sqlalchemy/orm/state.py", line 561, in _initialize_instance
    manager.dispatch.init(self, args, kwargs)
  File "/usr/local/lib/python3.8/dist-packages/sqlalchemy/event/attr.py", line 487, in __call__
    fn(*args, **kw)
  File "/usr/local/lib/python3.8/dist-packages/sqlalchemy/orm/mapper.py", line 4391, in _event_on_init
    instrumenting_mapper._check_configure()
  File "/usr/local/lib/python3.8/dist-packages/sqlalchemy/orm/mapper.py", line 2386, in _check_configure
    _configure_registries({self.registry}, cascade=True)
  File "/usr/local/lib/python3.8/dist-packages/sqlalchemy/orm/mapper.py", line 4199, in _configure_registries
    _do_configure_registries(registries, cascade)
  File "/usr/local/lib/python3.8/dist-packages/sqlalchemy/orm/mapper.py", line 4236, in _do_configure_registries
    raise e
sqlalchemy.exc.InvalidRequestError: One or more mappers failed to initialize - can't proceed with initialization of other mappers. Triggering mapper: 'Mapper[User(users)]'. Original exception was: When initializing mapper Mapper[User(users)], expression 'Review' failed to locate a name ('Review'). If this is a class name, consider adding this relationship() to the <class 'models.user.User'> class after both dependent classes have been defined.

======================================================================
ERROR: test_todict (test_models.test_user.test_User)
----------------------------------------------------------------------
Traceback (most recent call last):
  File "/AirBnB_clone_v2/tests/test_models/test_base_model.py", line 68, in test_todict
    i = self.value()
  File "<string>", line 4, in __init__
  File "/usr/local/lib/python3.8/dist-packages/sqlalchemy/orm/state.py", line 561, in _initialize_instance
    manager.dispatch.init(self, args, kwargs)
  File "/usr/local/lib/python3.8/dist-packages/sqlalchemy/event/attr.py", line 487, in __call__
    fn(*args, **kw)
  File "/usr/local/lib/python3.8/dist-packages/sqlalchemy/orm/mapper.py", line 4391, in _event_on_init
    instrumenting_mapper._check_configure()
  File "/usr/local/lib/python3.8/dist-packages/sqlalchemy/orm/mapper.py", line 2386, in _check_configure
    _configure_registries({self.registry}, cascade=True)
  File "/usr/local/lib/python3.8/dist-packages/sqlalchemy/orm/mapper.py", line 4199, in _configure_registries
    _do_configure_registries(registries, cascade)
  File "/usr/local/lib/python3.8/dist-packages/sqlalchemy/orm/mapper.py", line 4236, in _do_configure_registries
    raise e
sqlalchemy.exc.InvalidRequestError: One or more mappers failed to initialize - can't proceed with initialization of other mappers. Triggering mapper: 'Mapper[User(users)]'. Original exception was: When initializing mapper Mapper[User(users)], expression 'Review' failed to locate a name ('Review'). If this is a class name, consider adding this relationship() to the <class 'models.user.User'> class after both dependent classes have been defined.

======================================================================
ERROR: test_updated_at (test_models.test_user.test_User)
----------------------------------------------------------------------
Traceback (most recent call last):
  File "/AirBnB_clone_v2/tests/test_models/test_base_model.py", line 96, in test_updated_at
    new = self.value()
  File "<string>", line 4, in __init__
  File "/usr/local/lib/python3.8/dist-packages/sqlalchemy/orm/state.py", line 561, in _initialize_instance
    manager.dispatch.init(self, args, kwargs)
  File "/usr/local/lib/python3.8/dist-packages/sqlalchemy/event/attr.py", line 487, in __call__
    fn(*args, **kw)
  File "/usr/local/lib/python3.8/dist-packages/sqlalchemy/orm/mapper.py", line 4391, in _event_on_init
    instrumenting_mapper._check_configure()
  File "/usr/local/lib/python3.8/dist-packages/sqlalchemy/orm/mapper.py", line 2386, in _check_configure
    _configure_registries({self.registry}, cascade=True)
  File "/usr/local/lib/python3.8/dist-packages/sqlalchemy/orm/mapper.py", line 4199, in _configure_registries
    _do_configure_registries(registries, cascade)
  File "/usr/local/lib/python3.8/dist-packages/sqlalchemy/orm/mapper.py", line 4236, in _do_configure_registries
    raise e
sqlalchemy.exc.InvalidRequestError: One or more mappers failed to initialize - can't proceed with initialization of other mappers. Triggering mapper: 'Mapper[User(users)]'. Original exception was: When initializing mapper Mapper[User(users)], expression 'Review' failed to locate a name ('Review'). If this is a class name, consider adding this relationship() to the <class 'models.user.User'> class after both dependent classes have been defined.

======================================================================
FAIL: test_place_id (test_models.test_review.test_review)
----------------------------------------------------------------------
Traceback (most recent call last):
  File "/AirBnB_clone_v2/tests/test_models/test_review.py", line 19, in test_place_id
    self.assertEqual(type(new.place_id), str)
AssertionError: <class 'sqlalchemy.sql.schema.Column'> != <class 'str'>

======================================================================
FAIL: test_text (test_models.test_review.test_review)
----------------------------------------------------------------------
Traceback (most recent call last):
  File "/AirBnB_clone_v2/tests/test_models/test_review.py", line 29, in test_text
    self.assertEqual(type(new.text), str)
AssertionError: <class 'sqlalchemy.sql.schema.Column'> != <class 'str'>

======================================================================
FAIL: test_user_id (test_models.test_review.test_review)
----------------------------------------------------------------------
Traceback (most recent call last):
  File "/AirBnB_clone_v2/tests/test_models/test_review.py", line 24, in test_user_id
    self.assertEqual(type(new.user_id), str)
AssertionError: <class 'sqlalchemy.sql.schema.Column'> != <class 'str'>

----------------------------------------------------------------------
Ran 179 tests in 0.085s

FAILED (failures=3, errors=54, skipped=27)
