WARNING: MYSQL_OPT_RECONNECT is deprecated and will be removed in a future version.
/AirBnB_clone_v2/models/engine/db_storage.py:85: SAWarning: Column 'states.id' is marked as a member of the primary key for table 'states', but has no Python-side or server-side default generator indicated, nor does it indicate 'autoincrement=True' or 'nullable=True', and no explicit value is passed.  Primary key columns typically may not store NULL.
  self.__session.commit()
Traceback (most recent call last):
  File "/usr/local/lib/python3.8/dist-packages/sqlalchemy/engine/base.py", line 1965, in _exec_single_context
    self.dialect.do_execute(
  File "/usr/local/lib/python3.8/dist-packages/sqlalchemy/engine/default.py", line 921, in do_execute
    cursor.execute(statement, parameters)
  File "/usr/local/lib/python3.8/dist-packages/MySQLdb/cursors.py", line 206, in execute
    res = self._query(query)
  File "/usr/local/lib/python3.8/dist-packages/MySQLdb/cursors.py", line 319, in _query
    db.query(q)
  File "/usr/local/lib/python3.8/dist-packages/MySQLdb/connections.py", line 259, in query
    _mysql.connection.query(self, query)
MySQLdb._exceptions.IntegrityError: (1364, "Field 'id' doesn't have a default value")

The above exception was the direct cause of the following exception:

Traceback (most recent call last):
  File "./main_place_amenities.py", line 8, in <module>
    state.save()
  File "/AirBnB_clone_v2/models/base_model.py", line 44, in save
    storage.save()
  File "/AirBnB_clone_v2/models/engine/db_storage.py", line 85, in save
    self.__session.commit()
  File "/usr/local/lib/python3.8/dist-packages/sqlalchemy/orm/session.py", line 1923, in commit
    trans.commit(_to_root=True)
  File "<string>", line 2, in commit
  File "/usr/local/lib/python3.8/dist-packages/sqlalchemy/orm/state_changes.py", line 139, in _go
    ret_value = fn(self, *arg, **kw)
  File "/usr/local/lib/python3.8/dist-packages/sqlalchemy/orm/session.py", line 1239, in commit
    self._prepare_impl()
  File "<string>", line 2, in _prepare_impl
  File "/usr/local/lib/python3.8/dist-packages/sqlalchemy/orm/state_changes.py", line 139, in _go
    ret_value = fn(self, *arg, **kw)
  File "/usr/local/lib/python3.8/dist-packages/sqlalchemy/orm/session.py", line 1214, in _prepare_impl
    self.session.flush()
  File "/usr/local/lib/python3.8/dist-packages/sqlalchemy/orm/session.py", line 4179, in flush
    self._flush(objects)
  File "/usr/local/lib/python3.8/dist-packages/sqlalchemy/orm/session.py", line 4315, in _flush
    transaction.rollback(_capture_exception=True)
  File "/usr/local/lib/python3.8/dist-packages/sqlalchemy/util/langhelpers.py", line 147, in __exit__
    raise exc_value.with_traceback(exc_tb)
  File "/usr/local/lib/python3.8/dist-packages/sqlalchemy/orm/session.py", line 4275, in _flush
    flush_context.execute()
  File "/usr/local/lib/python3.8/dist-packages/sqlalchemy/orm/unitofwork.py", line 466, in execute
    rec.execute(self)
  File "/usr/local/lib/python3.8/dist-packages/sqlalchemy/orm/unitofwork.py", line 642, in execute
    util.preloaded.orm_persistence.save_obj(
  File "/usr/local/lib/python3.8/dist-packages/sqlalchemy/orm/persistence.py", line 93, in save_obj
    _emit_insert_statements(
  File "/usr/local/lib/python3.8/dist-packages/sqlalchemy/orm/persistence.py", line 1226, in _emit_insert_statements
    result = connection.execute(
  File "/usr/local/lib/python3.8/dist-packages/sqlalchemy/engine/base.py", line 1412, in execute
    return meth(
  File "/usr/local/lib/python3.8/dist-packages/sqlalchemy/sql/elements.py", line 515, in _execute_on_connection
    return connection._execute_clauseelement(
  File "/usr/local/lib/python3.8/dist-packages/sqlalchemy/engine/base.py", line 1635, in _execute_clauseelement
    ret = self._execute_context(
  File "/usr/local/lib/python3.8/dist-packages/sqlalchemy/engine/base.py", line 1844, in _execute_context
    return self._exec_single_context(
  File "/usr/local/lib/python3.8/dist-packages/sqlalchemy/engine/base.py", line 1984, in _exec_single_context
    self._handle_dbapi_exception(
  File "/usr/local/lib/python3.8/dist-packages/sqlalchemy/engine/base.py", line 2339, in _handle_dbapi_exception
    raise sqlalchemy_exception.with_traceback(exc_info[2]) from e
  File "/usr/local/lib/python3.8/dist-packages/sqlalchemy/engine/base.py", line 1965, in _exec_single_context
    self.dialect.do_execute(
  File "/usr/local/lib/python3.8/dist-packages/sqlalchemy/engine/default.py", line 921, in do_execute
    cursor.execute(statement, parameters)
  File "/usr/local/lib/python3.8/dist-packages/MySQLdb/cursors.py", line 206, in execute
    res = self._query(query)
  File "/usr/local/lib/python3.8/dist-packages/MySQLdb/cursors.py", line 319, in _query
    db.query(q)
  File "/usr/local/lib/python3.8/dist-packages/MySQLdb/connections.py", line 259, in query
    _mysql.connection.query(self, query)
sqlalchemy.exc.IntegrityError: (MySQLdb._exceptions.IntegrityError) (1364, "Field 'id' doesn't have a default value")
[SQL: INSERT INTO states (name, created_at, updated_at) VALUES (%s, %s, %s)]
[parameters: ('California', datetime.datetime(2023, 9, 12, 20, 28, 43, 289541), datetime.datetime(2023, 9, 12, 20, 28, 43, 363846))]
(Background on this error at: https://sqlalche.me/e/20/gkpj)
